======================================================================
FAIL: test_002 (unit_test.unit_test_case.TestSub)
----------------------------------------------------------------------
Traceback (most recent call last):
  File "D:\file\python\python_1\unit_test\unit_test_case.py", line 37, in test_002
    self.assertEqual(expected,res)
AssertionError: -2 != 4

======================================================================
FAIL: test_002 (unit_test.unit_test_case.TestSub)
----------------------------------------------------------------------
Traceback (most recent call last):
  File "D:\file\python\python_1\unit_test\unit_test_case.py", line 37, in test_002
    self.assertEqual(expected,res)
AssertionError: -2 != 4

----------------------------------------------------------------------
Ran 9 tests in 0.000s

FAILED (failures=2)
